<?xml version='1.0' encoding='utf-8'?>
<mujoco model="smplh_human_body">
  <default>
    <default class="human">
      <joint damping="50" armature="0.01"/>
      <geom type="capsule" condim="3" friction="1 0.5 0.001" density="1000"/>
    </default>
    
    <default class="human_collision">
      <geom type="capsule" solref="0.02 1.0" solimp="0.9 0.95 0.001" group="0" contype="1" conaffinity="1" rgba="0.8 0.6 0.5 0.8"/>
    </default>
    
    <default class="position_actuator">
      <position kp="2000" kv="50"/>
    </default>
  </default>
  <worldbody>
    <body name="Pelvis" pos="0 0 0">
      <freejoint name="root"/>
      <geom name="Pelvis_col" class="human_collision" fromto="0.0000 0.0000 0.0000 0.0586 0.0177 -0.0823" size="0.1000"/>
      <body name="L_Hip" pos="0.0586 0.0177 -0.0823">
        <joint name="L_Hip_x" type="hinge" axis="1 0 0" range="-3.14 3.14" class="human"/>
        <joint name="L_Hip_y" type="hinge" axis="0 1 0" range="-3.14 3.14" class="human"/>
        <joint name="L_Hip_z" type="hinge" axis="0 0 1" range="-3.14 3.14" class="human"/>
        <geom name="L_Hip_col" class="human_collision" fromto="0.0000 0.0000 0.0000 0.0435 -0.0080 -0.3865" size="0.0650"/>
        <body name="L_Knee" pos="0.0435 -0.0080 -0.3865">
          <joint name="L_Knee_x" type="hinge" axis="1 0 0" range="-3.14 3.14" class="human"/>
          <joint name="L_Knee_y" type="hinge" axis="0 1 0" range="-3.14 3.14" class="human"/>
          <joint name="L_Knee_z" type="hinge" axis="0 0 1" range="-3.14 3.14" class="human"/>
          <geom name="L_Knee_col" class="human_collision" fromto="0.0000 0.0000 0.0000 -0.0148 0.0374 -0.4269" size="0.0450"/>
          <body name="L_Ankle" pos="-0.0148 0.0374 -0.4269">
            <joint name="L_Ankle_x" type="hinge" axis="1 0 0" range="-3.14 3.14" class="human"/>
            <joint name="L_Ankle_y" type="hinge" axis="0 1 0" range="-3.14 3.14" class="human"/>
            <joint name="L_Ankle_z" type="hinge" axis="0 0 1" range="-3.14 3.14" class="human"/>
            <geom name="L_Ankle_col" class="human_collision" fromto="0.0000 0.0000 0.0000 0.0411 -0.1220 -0.0603" size="0.0350"/>
            <body name="L_Toe" pos="0.0411 -0.1220 -0.0603">
              <joint name="L_Toe_x" type="hinge" axis="1 0 0" range="-3.14 3.14" class="human"/>
              <joint name="L_Toe_y" type="hinge" axis="0 1 0" range="-3.14 3.14" class="human"/>
              <joint name="L_Toe_z" type="hinge" axis="0 0 1" range="-3.14 3.14" class="human"/>
              <geom name="L_Toe_col" class="human_collision" type="sphere" pos="0.0000 0.0000 0.0000" size="0.0350"/>
            </body>
          </body>
        </body>
      </body>
      <body name="R_Hip" pos="-0.0603 0.0135 -0.0905">
        <joint name="R_Hip_x" type="hinge" axis="1 0 0" range="-3.14 3.14" class="human"/>
        <joint name="R_Hip_y" type="hinge" axis="0 1 0" range="-3.14 3.14" class="human"/>
        <joint name="R_Hip_z" type="hinge" axis="0 0 1" range="-3.14 3.14" class="human"/>
        <geom name="R_Hip_col" class="human_collision" fromto="0.0000 0.0000 0.0000 -0.0433 0.0048 -0.3837" size="0.0650"/>
        <body name="R_Knee" pos="-0.0433 0.0048 -0.3837">
          <joint name="R_Knee_x" type="hinge" axis="1 0 0" range="-3.14 3.14" class="human"/>
          <joint name="R_Knee_y" type="hinge" axis="0 1 0" range="-3.14 3.14" class="human"/>
          <joint name="R_Knee_z" type="hinge" axis="0 0 1" range="-3.14 3.14" class="human"/>
          <geom name="R_Knee_col" class="human_collision" fromto="0.0000 0.0000 0.0000 0.0191 0.0346 -0.4200" size="0.0450"/>
          <body name="R_Ankle" pos="0.0191 0.0346 -0.4200">
            <joint name="R_Ankle_x" type="hinge" axis="1 0 0" range="-3.14 3.14" class="human"/>
            <joint name="R_Ankle_y" type="hinge" axis="0 1 0" range="-3.14 3.14" class="human"/>
            <joint name="R_Ankle_z" type="hinge" axis="0 0 1" range="-3.14 3.14" class="human"/>
            <geom name="R_Ankle_col" class="human_collision" fromto="0.0000 0.0000 0.0000 -0.0348 -0.1303 -0.0621" size="0.0350"/>
            <body name="R_Toe" pos="-0.0348 -0.1303 -0.0621">
              <joint name="R_Toe_x" type="hinge" axis="1 0 0" range="-3.14 3.14" class="human"/>
              <joint name="R_Toe_y" type="hinge" axis="0 1 0" range="-3.14 3.14" class="human"/>
              <joint name="R_Toe_z" type="hinge" axis="0 0 1" range="-3.14 3.14" class="human"/>
              <geom name="R_Toe_col" class="human_collision" type="sphere" pos="0.0000 0.0000 0.0000" size="0.0350"/>
            </body>
          </body>
        </body>
      </body>
      <body name="Torso" pos="0.0044 0.0384 0.1244">
        <joint name="Torso_x" type="hinge" axis="1 0 0" range="-3.14 3.14" class="human"/>
        <joint name="Torso_y" type="hinge" axis="0 1 0" range="-3.14 3.14" class="human"/>
        <joint name="Torso_z" type="hinge" axis="0 0 1" range="-3.14 3.14" class="human"/>
        <geom name="Torso_col" class="human_collision" fromto="0.0000 0.0000 0.0000 0.0045 -0.0268 0.1380" size="0.1200"/>
        <body name="Spine" pos="0.0045 -0.0268 0.1380">
          <joint name="Spine_x" type="hinge" axis="1 0 0" range="-3.14 3.14" class="human"/>
          <joint name="Spine_y" type="hinge" axis="0 1 0" range="-3.14 3.14" class="human"/>
          <joint name="Spine_z" type="hinge" axis="0 0 1" range="-3.14 3.14" class="human"/>
          <geom name="Spine_col" class="human_collision" fromto="0.0000 0.0000 0.0000 -0.0023 -0.0029 0.0560" size="0.1300"/>
          <body name="Chest" pos="-0.0023 -0.0029 0.0560">
            <joint name="Chest_x" type="hinge" axis="1 0 0" range="-3.14 3.14" class="human"/>
            <joint name="Chest_y" type="hinge" axis="0 1 0" range="-3.14 3.14" class="human"/>
            <joint name="Chest_z" type="hinge" axis="0 0 1" range="-3.14 3.14" class="human"/>
            <geom name="Chest_col" class="human_collision" fromto="0.0000 0.0000 0.0000 -0.0134 0.0335 0.2116" size="0.1300"/>
            <body name="Neck" pos="-0.0134 0.0335 0.2116">
              <joint name="Neck_x" type="hinge" axis="1 0 0" range="-3.14 3.14" class="human"/>
              <joint name="Neck_y" type="hinge" axis="0 1 0" range="-3.14 3.14" class="human"/>
              <joint name="Neck_z" type="hinge" axis="0 0 1" range="-3.14 3.14" class="human"/>
              <geom name="Neck_col" class="human_collision" fromto="0.0000 0.0000 0.0000 0.0101 -0.0504 0.0889" size="0.0400"/>
              <body name="Head" pos="0.0101 -0.0504 0.0889">
                <joint name="Head_x" type="hinge" axis="1 0 0" range="-3.14 3.14" class="human"/>
                <joint name="Head_y" type="hinge" axis="0 1 0" range="-3.14 3.14" class="human"/>
                <joint name="Head_z" type="hinge" axis="0 0 1" range="-3.14 3.14" class="human"/>
                <geom name="Head_col" class="human_collision" type="sphere" pos="0.0000 0.0000 0.0000" size="0.1000"/>
              </body>
            </body>
            <body name="L_Thorax" pos="0.0717 0.0189 0.1140">
              <joint name="L_Thorax_x" type="hinge" axis="1 0 0" range="-3.14 3.14" class="human"/>
              <joint name="L_Thorax_y" type="hinge" axis="0 1 0" range="-3.14 3.14" class="human"/>
              <joint name="L_Thorax_z" type="hinge" axis="0 0 1" range="-3.14 3.14" class="human"/>
              <geom name="L_Thorax_col" class="human_collision" fromto="0.0000 0.0000 0.0000 0.1229 0.0190 0.0452" size="0.0800"/>
              <body name="L_Shoulder" pos="0.1229 0.0190 0.0452">
                <joint name="L_Shoulder_x" type="hinge" axis="1 0 0" range="-3.14 3.14" class="human"/>
                <joint name="L_Shoulder_y" type="hinge" axis="0 1 0" range="-3.14 3.14" class="human"/>
                <joint name="L_Shoulder_z" type="hinge" axis="0 0 1" range="-3.14 3.14" class="human"/>
                <geom name="L_Shoulder_col" class="human_collision" fromto="0.0000 0.0000 0.0000 0.2553 0.0229 -0.0156" size="0.0400"/>
                <body name="L_Elbow" pos="0.2553 0.0229 -0.0156">
                  <joint name="L_Elbow_x" type="hinge" axis="1 0 0" range="-3.14 3.14" class="human"/>
                  <joint name="L_Elbow_y" type="hinge" axis="0 1 0" range="-3.14 3.14" class="human"/>
                  <joint name="L_Elbow_z" type="hinge" axis="0 0 1" range="-3.14 3.14" class="human"/>
                  <geom name="L_Elbow_col" class="human_collision" fromto="0.0000 0.0000 0.0000 0.2657 0.0074 0.0127" size="0.0350"/>
                  <body name="L_Wrist" pos="0.2657 0.0074 0.0127">
                    <joint name="L_Wrist_x" type="hinge" axis="1 0 0" range="-3.14 3.14" class="human"/>
                    <joint name="L_Wrist_y" type="hinge" axis="0 1 0" range="-3.14 3.14" class="human"/>
                    <joint name="L_Wrist_z" type="hinge" axis="0 0 1" range="-3.14 3.14" class="human"/>
                    <geom name="L_Wrist_col" class="human_collision" fromto="0.0000 0.0000 0.0000 0.1059 -0.0221 -0.0110" size="0.0250"/>
                  </body>
                </body>
              </body>
            </body>
            <body name="R_Thorax" pos="-0.0830 0.0237 0.1125">
              <joint name="R_Thorax_x" type="hinge" axis="1 0 0" range="-3.14 3.14" class="human"/>
              <joint name="R_Thorax_y" type="hinge" axis="0 1 0" range="-3.14 3.14" class="human"/>
              <joint name="R_Thorax_z" type="hinge" axis="0 0 1" range="-3.14 3.14" class="human"/>
              <geom name="R_Thorax_col" class="human_collision" fromto="0.0000 0.0000 0.0000 -0.1132 0.0085 0.0469" size="0.0800"/>
              <body name="R_Shoulder" pos="-0.1132 0.0085 0.0469">
                <joint name="R_Shoulder_x" type="hinge" axis="1 0 0" range="-3.14 3.14" class="human"/>
                <joint name="R_Shoulder_y" type="hinge" axis="0 1 0" range="-3.14 3.14" class="human"/>
                <joint name="R_Shoulder_z" type="hinge" axis="0 0 1" range="-3.14 3.14" class="human"/>
                <geom name="R_Shoulder_col" class="human_collision" fromto="0.0000 0.0000 0.0000 -0.2601 0.0313 -0.0144" size="0.0400"/>
                <body name="R_Elbow" pos="-0.2601 0.0313 -0.0144">
                  <joint name="R_Elbow_x" type="hinge" axis="1 0 0" range="-3.14 3.14" class="human"/>
                  <joint name="R_Elbow_y" type="hinge" axis="0 1 0" range="-3.14 3.14" class="human"/>
                  <joint name="R_Elbow_z" type="hinge" axis="0 0 1" range="-3.14 3.14" class="human"/>
                  <geom name="R_Elbow_col" class="human_collision" fromto="0.0000 0.0000 0.0000 -0.2691 0.0060 0.0068" size="0.0350"/>
                  <body name="R_Wrist" pos="-0.2691 0.0060 0.0068">
                    <joint name="R_Wrist_x" type="hinge" axis="1 0 0" range="-3.14 3.14" class="human"/>
                    <joint name="R_Wrist_y" type="hinge" axis="0 1 0" range="-3.14 3.14" class="human"/>
                    <joint name="R_Wrist_z" type="hinge" axis="0 0 1" range="-3.14 3.14" class="human"/>
                    <geom name="R_Wrist_col" class="human_collision" fromto="0.0000 0.0000 0.0000 -0.1041 -0.0262 -0.0088" size="0.0250"/>
                  </body>
                </body>
              </body>
            </body>
          </body>
        </body>
      </body>
    </body>
  </worldbody>
  <actuator>
    <position name="act_L_Hip_x" joint="L_Hip_x" class="position_actuator"/>
    <position name="act_L_Hip_y" joint="L_Hip_y" class="position_actuator"/>
    <position name="act_L_Hip_z" joint="L_Hip_z" class="position_actuator"/>
    <position name="act_R_Hip_x" joint="R_Hip_x" class="position_actuator"/>
    <position name="act_R_Hip_y" joint="R_Hip_y" class="position_actuator"/>
    <position name="act_R_Hip_z" joint="R_Hip_z" class="position_actuator"/>
    <position name="act_Torso_x" joint="Torso_x" class="position_actuator"/>
    <position name="act_Torso_y" joint="Torso_y" class="position_actuator"/>
    <position name="act_Torso_z" joint="Torso_z" class="position_actuator"/>
    <position name="act_L_Knee_x" joint="L_Knee_x" class="position_actuator"/>
    <position name="act_L_Knee_y" joint="L_Knee_y" class="position_actuator"/>
    <position name="act_L_Knee_z" joint="L_Knee_z" class="position_actuator"/>
    <position name="act_R_Knee_x" joint="R_Knee_x" class="position_actuator"/>
    <position name="act_R_Knee_y" joint="R_Knee_y" class="position_actuator"/>
    <position name="act_R_Knee_z" joint="R_Knee_z" class="position_actuator"/>
    <position name="act_Spine_x" joint="Spine_x" class="position_actuator"/>
    <position name="act_Spine_y" joint="Spine_y" class="position_actuator"/>
    <position name="act_Spine_z" joint="Spine_z" class="position_actuator"/>
    <position name="act_L_Ankle_x" joint="L_Ankle_x" class="position_actuator"/>
    <position name="act_L_Ankle_y" joint="L_Ankle_y" class="position_actuator"/>
    <position name="act_L_Ankle_z" joint="L_Ankle_z" class="position_actuator"/>
    <position name="act_R_Ankle_x" joint="R_Ankle_x" class="position_actuator"/>
    <position name="act_R_Ankle_y" joint="R_Ankle_y" class="position_actuator"/>
    <position name="act_R_Ankle_z" joint="R_Ankle_z" class="position_actuator"/>
    <position name="act_Chest_x" joint="Chest_x" class="position_actuator"/>
    <position name="act_Chest_y" joint="Chest_y" class="position_actuator"/>
    <position name="act_Chest_z" joint="Chest_z" class="position_actuator"/>
    <position name="act_L_Toe_x" joint="L_Toe_x" class="position_actuator"/>
    <position name="act_L_Toe_y" joint="L_Toe_y" class="position_actuator"/>
    <position name="act_L_Toe_z" joint="L_Toe_z" class="position_actuator"/>
    <position name="act_R_Toe_x" joint="R_Toe_x" class="position_actuator"/>
    <position name="act_R_Toe_y" joint="R_Toe_y" class="position_actuator"/>
    <position name="act_R_Toe_z" joint="R_Toe_z" class="position_actuator"/>
    <position name="act_Neck_x" joint="Neck_x" class="position_actuator"/>
    <position name="act_Neck_y" joint="Neck_y" class="position_actuator"/>
    <position name="act_Neck_z" joint="Neck_z" class="position_actuator"/>
    <position name="act_L_Thorax_x" joint="L_Thorax_x" class="position_actuator"/>
    <position name="act_L_Thorax_y" joint="L_Thorax_y" class="position_actuator"/>
    <position name="act_L_Thorax_z" joint="L_Thorax_z" class="position_actuator"/>
    <position name="act_R_Thorax_x" joint="R_Thorax_x" class="position_actuator"/>
    <position name="act_R_Thorax_y" joint="R_Thorax_y" class="position_actuator"/>
    <position name="act_R_Thorax_z" joint="R_Thorax_z" class="position_actuator"/>
    <position name="act_Head_x" joint="Head_x" class="position_actuator"/>
    <position name="act_Head_y" joint="Head_y" class="position_actuator"/>
    <position name="act_Head_z" joint="Head_z" class="position_actuator"/>
    <position name="act_L_Shoulder_x" joint="L_Shoulder_x" class="position_actuator"/>
    <position name="act_L_Shoulder_y" joint="L_Shoulder_y" class="position_actuator"/>
    <position name="act_L_Shoulder_z" joint="L_Shoulder_z" class="position_actuator"/>
    <position name="act_R_Shoulder_x" joint="R_Shoulder_x" class="position_actuator"/>
    <position name="act_R_Shoulder_y" joint="R_Shoulder_y" class="position_actuator"/>
    <position name="act_R_Shoulder_z" joint="R_Shoulder_z" class="position_actuator"/>
    <position name="act_L_Elbow_x" joint="L_Elbow_x" class="position_actuator"/>
    <position name="act_L_Elbow_y" joint="L_Elbow_y" class="position_actuator"/>
    <position name="act_L_Elbow_z" joint="L_Elbow_z" class="position_actuator"/>
    <position name="act_R_Elbow_x" joint="R_Elbow_x" class="position_actuator"/>
    <position name="act_R_Elbow_y" joint="R_Elbow_y" class="position_actuator"/>
    <position name="act_R_Elbow_z" joint="R_Elbow_z" class="position_actuator"/>
    <position name="act_L_Wrist_x" joint="L_Wrist_x" class="position_actuator"/>
    <position name="act_L_Wrist_y" joint="L_Wrist_y" class="position_actuator"/>
    <position name="act_L_Wrist_z" joint="L_Wrist_z" class="position_actuator"/>
    <position name="act_R_Wrist_x" joint="R_Wrist_x" class="position_actuator"/>
    <position name="act_R_Wrist_y" joint="R_Wrist_y" class="position_actuator"/>
    <position name="act_R_Wrist_z" joint="R_Wrist_z" class="position_actuator"/>
  </actuator>
</mujoco>
